Workbook

Sheet PNL
D1: Remaining | E1: Tiktok | F1: Facebook
A2: Balance | B2: =D2/'Client Details'!H1 -> 0.034333333 | C2: Balance BDT | D2: =sum(E4:E1001) -> 5.15 | E2: =D2/'Client Details'!F1 -> 0.034333333 | F2: =D2/'Client Details'!D1 -> 0.034333333
A3: Date | B3: Received | C3: Burnt US | D3: Platform | E3: Remaining | F3: Burnt | G3: Payment Note
A4: 46089 | B4: ৳100.00 | D4: Facebook | G4: 08/03/26/cli-1439/lst-bkash/pay-100
A5: 45990 | B5: 100 | C5: 0.55 | D5: Facebook | E5: =B5-F5 -> 20.25 | F5: =IF(ISBLANK(D5) ,0,IF(D5="Tiktok",C5*155,C5*145)) -> 79.75 | G5: ADJ
A6: 45991 | B6: 1500 | C6: 0.2 | D6: Facebook | E6: =B6-F6 -> 1471 | F6: =IF(ISBLANK(D6) ,0,IF(D6="Tiktok",C6*155,C6*145)) -> 29 | G6: 1/12/25/cli-1439/lst-bank/pay-1500
A7: 45992 | C7: 4.58 | D7: Facebook | E7: =B7-F7 -> -664.1 | F7: =IF(ISBLANK(D7) ,0,IF(D7="Tiktok",C7*155,C7*145)) -> 664.1
A8: 45993 | C8: 4.78 | D8: Facebook | E8: =B8-F8 -> -693.1 | F8: =IF(ISBLANK(D8) ,0,IF(D8="Tiktok",C8*155,C8*145)) -> 693.1
A9: 45994 | B9: 2000 | C9: 10.56 | D9: Facebook | E9: =B9-F9 -> 468.8 | F9: =IF(ISBLANK(D9) ,0,IF(D9="Tiktok",C9*155,C9*145)) -> 1531.2 | G9: 03/12/25/cli-1439/lst-bank/pay-2000
A10: 45995 | C10: 8.73 | D10: Facebook | E10: =B10-F10 -> -1265.85 | F10: =IF(ISBLANK(D10) ,0,IF(D10="Tiktok",C10*155,C10*145)) -> 1265.85
A11: 45996 | C11: 6.74 | D11: Facebook | E11: =B11-F11 -> -977.3 | F11: =IF(ISBLANK(D11) ,0,IF(D11="Tiktok",C11*155,C11*145)) -> 977.3
A12: 45997 | B12: 2500 | C12: 1 | D12: Facebook | E12: =B12-F12 -> 2355 | F12: =IF(ISBLANK(D12) ,0,IF(D12="Tiktok",C12*155,C12*145)) -> 145 | G12: 06/12/25/cli-1439/lst-bank/pay-2500
A13: 45998 | C13: 0 | D13: Facebook | E13: =B13-F13 -> 0 | F13: =IF(ISBLANK(D13) ,0,IF(D13="Tiktok",C13*155,C13*145)) -> 0
A14: 45999 | C14: 3 | D14: Facebook | E14: =B14-F14 -> -435 | F14: =IF(ISBLANK(D14) ,0,IF(D14="Tiktok",C14*155,C14*145)) -> 435
A15: 46000 | B15: 2500 | C15: 4.91 | D15: Facebook | E15: =B15-F15 -> 1788.05 | F15: =IF(ISBLANK(D15) ,0,IF(D15="Tiktok",C15*155,C15*145)) -> 711.95 | G15: 09/12/25/cli-1439/lst-bank/pay-2500
A16: 46001 | C16: 7.67 | D16: Facebook | E16: =B16-F16 -> -1112.15 | F16: =IF(ISBLANK(D16) ,0,IF(D16="Tiktok",C16*155,C16*145)) -> 1112.15
A17: 46002 | C17: 6.44 | D17: Facebook | E17: =B17-F17 -> -933.8 | F17: =IF(ISBLANK(D17) ,0,IF(D17="Tiktok",C17*155,C17*145)) -> 933.8
D18: Facebook | E18: =B18-F18 -> 0 | F18: =IF(ISBLANK(D18) ,0,IF(D18="Tiktok",C18*155,C18*145)) -> 0
D19: Facebook | E19: =B19-F19 -> 0 | F19: =IF(ISBLANK(D19) ,0,IF(D19="Tiktok",C19*155,C19*145)) -> 0
D20: Facebook | E20: =B20-F20 -> 0 | F20: =IF(ISBLANK(D20) ,0,IF(D20="Tiktok",C20*155,C20*145)) -> 0
A21: 46010 | B21: 1500 | C21: 1.66 | D21: Facebook | E21: =B21-F21 -> 1259.3 | F21: =IF(ISBLANK(D21) ,0,IF(D21="Tiktok",C21*155,C21*145)) -> 240.7 | G21: 19/12/25/cl-1439/lst-bank/pay-1500
A22: 46011 | C22: 4.98 | D22: Facebook | E22: =B22-F22 -> -722.1 | F22: =IF(ISBLANK(D22) ,0,IF(D22="Tiktok",C22*155,C22*145)) -> 722.1
A23: 46012 | C23: 4.82 | D23: Facebook | E23: =B23-F23 -> -698.9 | F23: =IF(ISBLANK(D23) ,0,IF(D23="Tiktok",C23*155,C23*145)) -> 698.9
A24: 46013 | B24: 1000 | C24: 5.51 | D24: Facebook | E24: =B24-F24 -> 201.05 | F24: =IF(ISBLANK(D24) ,0,IF(D24="Tiktok",C24*155,C24*145)) -> 798.95 | G24: 22/12/25/cli-1439/lst-bank/pay-1000
A25: 46014 | C25: 7.38 | D25: Facebook | E25: =B25-F25 -> -1070.1 | F25: =IF(ISBLANK(D25) ,0,IF(D25="Tiktok",C25*155,C25*145)) -> 1070.1
A26: 46015 | C26: 0.46 | D26: Facebook | E26: =B26-F26 -> -66.7 | F26: =IF(ISBLANK(D26) ,0,IF(D26="Tiktok",C26*155,C26*145)) -> 66.7
D27: Facebook | E27: =B27-F27 -> 0 | F27: =IF(ISBLANK(D27) ,0,IF(D27="Tiktok",C27*155,C27*145)) -> 0
D28: Facebook | E28: =B28-F28 -> 0 | F28: =IF(ISBLANK(D28) ,0,IF(D28="Tiktok",C28*155,C28*145)) -> 0
A29: 46021 | B29: 1100 | D29: Facebook | E29: =B29-F29 -> 1100 | F29: =IF(ISBLANK(D29) ,0,IF(D29="Tiktok",C29*155,C29*145)) -> 0 | G29: 30/12/25/cli-1439/lst-bank/pay-1100
D30: Facebook | E30: =B30-F30 -> 0 | F30: =IF(ISBLANK(D30) ,0,IF(D30="Tiktok",C30*155,C30*145)) -> 0
D31: Facebook | E31: =B31-F31 -> 0 | F31: =IF(ISBLANK(D31) ,0,IF(D31="Tiktok",C31*155,C31*145)) -> 0
D32: Facebook | E32: =B32-F32 -> 0 | F32: =IF(ISBLANK(D32) ,0,IF(D32="Tiktok",C32*155,C32*145)) -> 0
A33: 46026 | B33: 1500 | D33: Facebook | E33: =B33-F33 -> 1500 | F33: =IF(ISBLANK(D33) ,0,IF(D33="Tiktok",C33*155,C33*145)) -> 0 | G33: 05/01/26/cli-1439/lst-bank/pay-1500
A34: 46027 | C34: 0.07 | D34: Facebook | E34: =B34-F34 -> -10.15 | F34: =IF(ISBLANK(D34) ,0,IF(D34="Tiktok",C34*155,C34*145)) -> 10.15
A35: 46028 | C35: 0.33 | D35: Facebook | E35: =B35-F35 -> -47.85 | F35: =IF(ISBLANK(D35) ,0,IF(D35="Tiktok",C35*155,C35*145)) -> 47.85
A36: 46029 | C36: 0.97 | D36: Facebook | E36: =B36-F36 -> -140.65 | F36: =IF(ISBLANK(D36) ,0,IF(D36="Tiktok",C36*155,C36*145)) -> 140.65
A37: 46030 | C37: 0.08 | D37: Facebook | E37: =B37-F37 -> -11.6 | F37: =IF(ISBLANK(D37) ,0,IF(D37="Tiktok",C37*155,C37*145)) -> 11.6
D38: Facebook | E38: =B38-F38 -> 0 | F38: =IF(ISBLANK(D38) ,0,IF(D38="Tiktok",C38*155,C38*145)) -> 0
D39: Facebook | E39: =B39-F39 -> 0 | F39: =IF(ISBLANK(D39) ,0,IF(D39="Tiktok",C39*155,C39*145)) -> 0
D40: Facebook | E40: =B40-F40 -> 0 | F40: =IF(ISBLANK(D40) ,0,IF(D40="Tiktok",C40*155,C40*145)) -> 0
...

Sheet Campaign Management
A1: Total Budget | B1: =SUM(H5:H40) -> 0 | C1: Total Camp Due | D1: =B2-B1 -> 5.15 | F1: Tiktok Budget | G1: FB Budget | H1: Tiktok Due | I1: FB Due
A2: Total Paid | B2: =SUM(PNL!E4:E1000) -> 5.15 | C2: Daily Due | D2: =SUMIF(I5:I1000, "<>Completed", G5:G1000) -> 0 | F2: =SUMIF(B5:B1000, "TikTok", H5:H1000) -> 0 | G2: =SUMIF(B5:B1000, "Facebook", H5:H1000) -> 0 | H2: =SUMIF(B5:B1000, "TikTok", K5:K1000) -> 0 | I2: =SUMIF(B5:B1000, "Facebook", K5:K1000) -> 0
A3: Today | B3: =TODAY() -> 46089
A4: Start | B4: Platform | C4: Ads Account | D4: Camp Code | E4: Budget US | F4: Duration | G4: Daily Due | H4: Budget BD | I4: Status | J4: Executive | K4: Due | L4: End | M4: Remaining
G5: =IFERROR(H5/F5, 0) -> 0 | H5: =IF(ISBLANK(B5) ,0,IF(B5="Tiktok",E5*'Client Details'!$F$1,E5*'Client Details'!$D$1)) -> 0 | I5: =IF(M5<0, "COMPLETED", "") | K5: =IF(M5>0, G5*M5, 0) -> 0 | L5: =IF(A5="", 0, A5+F5) -> 0 | M5: =IF(OR(L5="", L5=0), 0, L5-$B$3) -> 0
G6: =IFERROR(H6/F6, 0) -> 0 | H6: =IF(ISBLANK(B6) ,0,IF(B6="Tiktok",E6*'Client Details'!$F$1,E6*'Client Details'!$D$1)) -> 0 | I6: =IF(M6<0, "COMPLETED", "") | K6: =IF(M6>0, G6*M6, 0) -> 0 | L6: =IF(A6="", 0, A6+F6) -> 0 | M6: =IF(OR(L6="", L6=0), 0, L6-$B$3) -> 0
G7: =IFERROR(H7/F7, 0) -> 0 | H7: =IF(ISBLANK(B7) ,0,IF(B7="Tiktok",E7*'Client Details'!$F$1,E7*'Client Details'!$D$1)) -> 0 | I7: =IF(M7<0, "COMPLETED", "") | K7: =IF(M7>0, G7*M7, 0) -> 0 | L7: =IF(A7="", 0, A7+F7) -> 0 | M7: =IF(OR(L7="", L7=0), 0, L7-$B$3) -> 0
G8: =IFERROR(H8/F8, 0) -> 0 | H8: =IF(ISBLANK(B8) ,0,IF(B8="Tiktok",E8*'Client Details'!$F$1,E8*'Client Details'!$D$1)) -> 0 | I8: =IF(M8<0, "COMPLETED", "") | K8: =IF(M8>0, G8*M8, 0) -> 0 | L8: =IF(A8="", 0, A8+F8) -> 0 | M8: =IF(OR(L8="", L8=0), 0, L8-$B$3) -> 0
G9: =IFERROR(H9/F9, 0) -> 0 | H9: =IF(ISBLANK(B9) ,0,IF(B9="Tiktok",E9*'Client Details'!$F$1,E9*'Client Details'!$D$1)) -> 0 | I9: =IF(M9<0, "COMPLETED", "") | K9: =IF(M9>0, G9*M9, 0) -> 0 | L9: =IF(A9="", 0, A9+F9) -> 0 | M9: =IF(OR(L9="", L9=0), 0, L9-$B$3) -> 0
G10: =IFERROR(H10/F10, 0) -> 0 | H10: =IF(ISBLANK(B10) ,0,IF(B10="Tiktok",E10*'Client Details'!$F$1,E10*'Client Details'!$D$1)) -> 0 | I10: =IF(M10<0, "COMPLETED", "") | K10: =IF(M10>0, G10*M10, 0) -> 0 | L10: =IF(A10="", 0, A10+F10) -> 0 | M10: =IF(OR(L10="", L10=0), 0, L10-$B$3) -> 0
G11: =IFERROR(H11/F11, 0) -> 0 | H11: =IF(ISBLANK(B11) ,0,IF(B11="Tiktok",E11*'Client Details'!$F$1,E11*'Client Details'!$D$1)) -> 0 | I11: =IF(M11<0, "COMPLETED", "") | K11: =IF(M11>0, G11*M11, 0) -> 0 | L11: =IF(A11="", 0, A11+F11) -> 0 | M11: =IF(OR(L11="", L11=0), 0, L11-$B$3) -> 0
G12: =IFERROR(H12/F12, 0) -> 0 | H12: =IF(ISBLANK(B12) ,0,IF(B12="Tiktok",E12*'Client Details'!$F$1,E12*'Client Details'!$D$1)) -> 0 | I12: =IF(M12<0, "COMPLETED", "") | K12: =IF(M12>0, G12*M12, 0) -> 0 | L12: =IF(A12="", 0, A12+F12) -> 0 | M12: =IF(OR(L12="", L12=0), 0, L12-$B$3) -> 0
G13: =IFERROR(H13/F13, 0) -> 0 | H13: =IF(ISBLANK(B13) ,0,IF(B13="Tiktok",E13*'Client Details'!$F$1,E13*'Client Details'!$D$1)) -> 0 | I13: =IF(M13<0, "COMPLETED", "") | K13: =IF(M13>0, G13*M13, 0) -> 0 | L13: =IF(A13="", 0, A13+F13) -> 0 | M13: =IF(OR(L13="", L13=0), 0, L13-$B$3) -> 0
G14: =IFERROR(H14/F14, 0) -> 0 | H14: =IF(ISBLANK(B14) ,0,IF(B14="Tiktok",E14*'Client Details'!$F$1,E14*'Client Details'!$D$1)) -> 0 | I14: =IF(M14<0, "COMPLETED", "") | K14: =IF(M14>0, G14*M14, 0) -> 0 | L14: =IF(A14="", 0, A14+F14) -> 0 | M14: =IF(OR(L14="", L14=0), 0, L14-$B$3) -> 0
G15: =IFERROR(H15/F15, 0) -> 0 | H15: =IF(ISBLANK(B15) ,0,IF(B15="Tiktok",E15*'Client Details'!$F$1,E15*'Client Details'!$D$1)) -> 0 | I15: =IF(M15<0, "COMPLETED", "") | K15: =IF(M15>0, G15*M15, 0) -> 0 | L15: =IF(A15="", 0, A15+F15) -> 0 | M15: =IF(OR(L15="", L15=0), 0, L15-$B$3) -> 0
G16: =IFERROR(H16/F16, 0) -> 0 | H16: =IF(ISBLANK(B16) ,0,IF(B16="Tiktok",E16*'Client Details'!$F$1,E16*'Client Details'!$D$1)) -> 0 | I16: =IF(M16<0, "COMPLETED", "") | K16: =IF(M16>0, G16*M16, 0) -> 0 | L16: =IF(A16="", 0, A16+F16) -> 0 | M16: =IF(OR(L16="", L16=0), 0, L16-$B$3) -> 0
... G33: =IFERROR(H33/F33, 0) -> 0 | H33: =IF(ISBLANK(B33) ,0,IF(B33="Tiktok",E33*'Client Details'!$F$1,E33*'Client Details'!$D$1)) -> 0 | I33: =IF(M33<0, "COMPLETED", "") | K33: =IF(M33>0, G33*M33, 0) -> 0 | L33: =IF(A33="", 0, A33+F33) -> 0 | M33: =IF(OR(L33="", L33=0), 0, L33-$B$3) -> 0
G34: =IFERROR(H34/F34, 0) -> 0 | H34: =IF(ISBLANK(B34) ,0,IF(B34="Tiktok",E34*'Client Details'!$F$1,E34*'Client Details'!$D$1)) -> 0 | K34: =IF(M34>0, G34*M34, 0) -> 0 | L34: =IF(A34="", 0, A34+F34) -> 0 | M34: =IF(OR(L34="", L34=0), 0, L34-$B$3) -> 0
G35: =IFERROR(H35/F35, 0) -> 0 | H35: =IF(ISBLANK(B35) ,0,IF(B35="Tiktok",E35*'Client Details'!$F$1,E35*'Client Details'!$D$1)) -> 0 | K35: =IF(M35>0, G35*M35, 0) -> 0 | L35: =IF(A35="", 0, A35+F35) -> 0 | M35: =IF(OR(L35="", L35=0), 0, L35-$B$3) -> 0
G36: =IFERROR(H36/F36, 0) -> 0 | H36: =IF(ISBLANK(B36) ,0,IF(B36="Tiktok",E36*'Client Details'!$F$1,E36*'Client Details'!$D$1)) -> 0 | K36: =IF(M36>0, G36*M36, 0) -> 0 | L36: =IF(A36="", 0, A36+F36) -> 0 | M36: =IF(OR(L36="", L36=0), 0, L36-$B$3) -> 0
G37: =IFERROR(H37/F37, 0) -> 0 | H37: =IF(ISBLANK(B37) ,0,IF(B37="Tiktok",E37*'Client Details'!$F$1,E37*'Client Details'!$D$1)) -> 0 | K37: =IF(M37>0, G37*M37, 0) -> 0 | L37: =IF(A37="", 0, A37+F37) -> 0 | M37: =IF(OR(L37="", L37=0), 0, L37-$B$3) -> 0
G38: =IFERROR(H38/F38, 0) -> 0 | H38: =IF(ISBLANK(B38) ,0,IF(B38="Tiktok",E38*'Client Details'!$F$1,E38*'Client Details'!$D$1)) -> 0 | K38: =IF(M38>0, G38*M38, 0) -> 0 | L38: =IF(A38="", 0, A38+F38) -> 0 | M38: =IF(OR(L38="", L38=0), 0, L38-$B$3) -> 0
G39: =IFERROR(H39/F39, 0) -> 0 | H39: =IF(ISBLANK(B39) ,0,IF(B39="Tiktok",E39*'Client Details'!$F$1,E39*'Client Details'!$D$1)) -> 0 | K39: =IF(M39>0, G39*M39, 0) -> 0 | L39: =IF(A39="", 0, A39+F39) -> 0 | M39: =IF(OR(L39="", L39=0), 0, L39-$B$3) -> 0
G40: =IFERROR(H40/F40, 0) -> 0 | H40: =IF(ISBLANK(B40) ,0,IF(B40="Tiktok",E40*'Client Details'!$F$1,E40*'Client Details'!$D$1)) -> 0 | K40: =IF(M40>0, G40*M40, 0) -> 0 | L40: =IF(A40="", 0, A40+F40) -> 0 | M40: =IF(OR(L40="", L40=0), 0, L40-$B$3) -> 0
H41: =IF(ISBLANK(B41) ,0,IF(B41="Tiktok",E41*'Client Details'!$F$1,E41*'Client Details'!$D$1)) -> 0
H42: =IF(ISBLANK(B42) ,0,IF(B42="Tiktok",E42*'Client Details'!$F$1,E42*'Client Details'!$D$1)) -> 0
H43: =IF(ISBLANK(B43) ,0,IF(B43="Tiktok",E43*'Client Details'!$F$1,E43*'Client Details'!$D$1)) -> 0
H44: =IF(ISBLANK(B44) ,0,IF(B44="Tiktok",E44*'Client Details'!$F$1,E44*'Client Details'!$D$1)) -> 0
H45: =IF(ISBLANK(B45) ,0,IF(B45="Tiktok",E45*'Client Details'!$F$1,E45*'Client Details'!$D$1)) -> 0
H46: =IF(ISBLANK(B46) ,0,IF(B46="Tiktok",E46*'Client Details'!$F$1,E46*'Client Details'!$D$1)) -> 0
H47: =IF(ISBLANK(B47) ,0,IF(B47="Tiktok",E47*'Client Details'!$F$1,E47*'Client Details'!$D$1)) -> 0
H48: =IF(ISBLANK(B48) ,0,IF(B48="Tiktok",E48*'Client Details'!$F$1,E48*'Client Details'!$D$1)) -> 0
H49: =IF(ISBLANK(B49) ,0,IF(B49="Tiktok",E49*'Client Details'!$F$1,E49*'Client Details'!$D$1)) -> 0
H50: =IF(ISBLANK(B50) ,0,IF(B50="Tiktok",E50*'Client Details'!$F$1,E50*'Client Details'!$D$1)) -> 0
H51: =IF(ISBLANK(B51) ,0,IF(B51="Tiktok",E51*'Client Details'!$F$1,E51*'Client Details'!$D$1)) -> 0
H52: =IF(ISBLANK(B52) ,0,IF(B52="Tiktok",E52*'Client Details'!$F$1,E52*'Client Details'!$D$1)) -> 0
H53: =IF(ISBLANK(B53) ,0,IF(B53="Tiktok",E53*'Client Details'!$F$1,E53*'Client Details'!$D$1)) -> 0

Sheet Client Details
A1: Client Code | B1: Cli 1439 | C1: FB Rate | D1: 150 | E1: Tiktok Rate | F1: 150 | G1: Sum Rate | H1: =(D1+F1)/2 -> 150
A2: Camp Budget | B2: Balance | C2: Camp Due | D2: Daily Due | E2: Tiktok $ | F2: FB $
A3: ='Campaign Management'!B1 -> 0 | B3: =PNL!D2 -> 5.15 | C3: ='Campaign Management'!D1 -> 5.15 | D3: ='Campaign Management'!D2 -> 0 | E3: =PNL!E2 -> 0.034333333 | F3: =PNL!F2 -> 0.034333333

Sheet Monthly Reports
